Traceback (most recent call last):
  File "/home/vboxuser/Desktop/FocoRadical/extract.py", line 19, in <module>
    driver = webdriver.Chrome(service=Service(ChromeDriverManager().install()), options=options)
             ^^^^^^^^^^^^^^^^^^^^^^^^^^^^^^^^^^^^^^^^^^^^^^^^^^^^^^^^^^^^^^^^^^^^^^^^^^^^^^^^^^^
  File "/home/vboxuser/Desktop/FocoRadical/venv/lib/python3.12/site-packages/selenium/webdriver/chrome/webdriver.py", line 47, in __init__
    super().__init__(
  File "/home/vboxuser/Desktop/FocoRadical/venv/lib/python3.12/site-packages/selenium/webdriver/chromium/webdriver.py", line 69, in __init__
    super().__init__(command_executor=executor, options=options)
  File "/home/vboxuser/Desktop/FocoRadical/venv/lib/python3.12/site-packages/selenium/webdriver/remote/webdriver.py", line 261, in __init__
    self.start_session(capabilities)
  File "/home/vboxuser/Desktop/FocoRadical/venv/lib/python3.12/site-packages/selenium/webdriver/remote/webdriver.py", line 362, in start_session
    response = self.execute(Command.NEW_SESSION, caps)["value"]
               ^^^^^^^^^^^^^^^^^^^^^^^^^^^^^^^^^^^^^^^
  File "/home/vboxuser/Desktop/FocoRadical/venv/lib/python3.12/site-packages/selenium/webdriver/remote/webdriver.py", line 454, in execute
    self.error_handler.check_response(response)
  File "/home/vboxuser/Desktop/FocoRadical/venv/lib/python3.12/site-packages/selenium/webdriver/remote/errorhandler.py", line 232, in check_response
    raise exception_class(message, screen, stacktrace)
selenium.common.exceptions.SessionNotCreatedException: Message: session not created: probably user data directory is already in use, please specify a unique value for --user-data-dir argument, or don't use --user-data-dir; For documentation on this error, please visit: https://www.selenium.dev/documentation/webdriver/troubleshooting/errors#sessionnotcreatedexception
Stacktrace:
#0 0x5b51433f687a <unknown>
#1 0x5b5142e9b2e0 <unknown>
#2 0x5b5142ed57bd <unknown>
#3 0x5b5142ed0ad7 <unknown>
#4 0x5b5142f20e9e <unknown>
#5 0x5b5142f20466 <unknown>
#6 0x5b5142f12683 <unknown>
#7 0x5b5142edeb5b <unknown>
#8 0x5b5142edff31 <unknown>
#9 0x5b51433bb7cb <unknown>
#10 0x5b51433bf5d4 <unknown>
#11 0x5b51433a22c9 <unknown>
#12 0x5b51433c0178 <unknown>
#13 0x5b51433866bf <unknown>
#14 0x5b51433e3e78 <unknown>
#15 0x5b51433e4056 <unknown>
#16 0x5b51433f5b96 <unknown>
#17 0x71500ec9caa4 <unknown>
#18 0x71500ed29c3c <unknown>

Traceback (most recent call last):
  File "/home/vboxuser/Desktop/FocoRadical/extract.py", line 19, in <module>
    driver = webdriver.Chrome(service=Service(ChromeDriverManager().install()), options=options)
             ^^^^^^^^^^^^^^^^^^^^^^^^^^^^^^^^^^^^^^^^^^^^^^^^^^^^^^^^^^^^^^^^^^^^^^^^^^^^^^^^^^^
  File "/home/vboxuser/Desktop/FocoRadical/venv/lib/python3.12/site-packages/selenium/webdriver/chrome/webdriver.py", line 47, in __init__
    super().__init__(
  File "/home/vboxuser/Desktop/FocoRadical/venv/lib/python3.12/site-packages/selenium/webdriver/chromium/webdriver.py", line 69, in __init__
    super().__init__(command_executor=executor, options=options)
  File "/home/vboxuser/Desktop/FocoRadical/venv/lib/python3.12/site-packages/selenium/webdriver/remote/webdriver.py", line 261, in __init__
    self.start_session(capabilities)
  File "/home/vboxuser/Desktop/FocoRadical/venv/lib/python3.12/site-packages/selenium/webdriver/remote/webdriver.py", line 362, in start_session
    response = self.execute(Command.NEW_SESSION, caps)["value"]
               ^^^^^^^^^^^^^^^^^^^^^^^^^^^^^^^^^^^^^^^
  File "/home/vboxuser/Desktop/FocoRadical/venv/lib/python3.12/site-packages/selenium/webdriver/remote/webdriver.py", line 454, in execute
    self.error_handler.check_response(response)
  File "/home/vboxuser/Desktop/FocoRadical/venv/lib/python3.12/site-packages/selenium/webdriver/remote/errorhandler.py", line 232, in check_response
    raise exception_class(message, screen, stacktrace)
selenium.common.exceptions.SessionNotCreatedException: Message: session not created: probably user data directory is already in use, please specify a unique value for --user-data-dir argument, or don't use --user-data-dir; For documentation on this error, please visit: https://www.selenium.dev/documentation/webdriver/troubleshooting/errors#sessionnotcreatedexception
Stacktrace:
#0 0x5caedc30f87a <unknown>
#1 0x5caedbdb42e0 <unknown>
#2 0x5caedbdee7bd <unknown>
#3 0x5caedbde9ad7 <unknown>
#4 0x5caedbe39e9e <unknown>
#5 0x5caedbe39466 <unknown>
#6 0x5caedbe2b683 <unknown>
#7 0x5caedbdf7b5b <unknown>
#8 0x5caedbdf8f31 <unknown>
#9 0x5caedc2d47cb <unknown>
#10 0x5caedc2d85d4 <unknown>
#11 0x5caedc2bb2c9 <unknown>
#12 0x5caedc2d9178 <unknown>
#13 0x5caedc29f6bf <unknown>
#14 0x5caedc2fce78 <unknown>
#15 0x5caedc2fd056 <unknown>
#16 0x5caedc30eb96 <unknown>
#17 0x7324e5e9caa4 <unknown>
#18 0x7324e5f29c3c <unknown>

Traceback (most recent call last):
  File "/home/vboxuser/Desktop/FocoRadical/extract.py", line 19, in <module>
    driver = webdriver.Chrome(service=Service(ChromeDriverManager().install()), options=options)
             ^^^^^^^^^^^^^^^^^^^^^^^^^^^^^^^^^^^^^^^^^^^^^^^^^^^^^^^^^^^^^^^^^^^^^^^^^^^^^^^^^^^
  File "/home/vboxuser/Desktop/FocoRadical/venv/lib/python3.12/site-packages/selenium/webdriver/chrome/webdriver.py", line 47, in __init__
    super().__init__(
  File "/home/vboxuser/Desktop/FocoRadical/venv/lib/python3.12/site-packages/selenium/webdriver/chromium/webdriver.py", line 69, in __init__
    super().__init__(command_executor=executor, options=options)
  File "/home/vboxuser/Desktop/FocoRadical/venv/lib/python3.12/site-packages/selenium/webdriver/remote/webdriver.py", line 261, in __init__
    self.start_session(capabilities)
  File "/home/vboxuser/Desktop/FocoRadical/venv/lib/python3.12/site-packages/selenium/webdriver/remote/webdriver.py", line 362, in start_session
    response = self.execute(Command.NEW_SESSION, caps)["value"]
               ^^^^^^^^^^^^^^^^^^^^^^^^^^^^^^^^^^^^^^^
  File "/home/vboxuser/Desktop/FocoRadical/venv/lib/python3.12/site-packages/selenium/webdriver/remote/webdriver.py", line 454, in execute
    self.error_handler.check_response(response)
  File "/home/vboxuser/Desktop/FocoRadical/venv/lib/python3.12/site-packages/selenium/webdriver/remote/errorhandler.py", line 232, in check_response
    raise exception_class(message, screen, stacktrace)
selenium.common.exceptions.SessionNotCreatedException: Message: session not created: probably user data directory is already in use, please specify a unique value for --user-data-dir argument, or don't use --user-data-dir; For documentation on this error, please visit: https://www.selenium.dev/documentation/webdriver/troubleshooting/errors#sessionnotcreatedexception
Stacktrace:
#0 0x60f5f37f187a <unknown>
#1 0x60f5f32962e0 <unknown>
#2 0x60f5f32d07bd <unknown>
#3 0x60f5f32cbad7 <unknown>
#4 0x60f5f331be9e <unknown>
#5 0x60f5f331b466 <unknown>
#6 0x60f5f330d683 <unknown>
#7 0x60f5f32d9b5b <unknown>
#8 0x60f5f32daf31 <unknown>
#9 0x60f5f37b67cb <unknown>
#10 0x60f5f37ba5d4 <unknown>
#11 0x60f5f379d2c9 <unknown>
#12 0x60f5f37bb178 <unknown>
#13 0x60f5f37816bf <unknown>
#14 0x60f5f37dee78 <unknown>
#15 0x60f5f37df056 <unknown>
#16 0x60f5f37f0b96 <unknown>
#17 0x7b5d5e69caa4 <unknown>
#18 0x7b5d5e729c3c <unknown>

Traceback (most recent call last):
  File "/home/vboxuser/Desktop/FocoRadical/extract.py", line 19, in <module>
    driver = webdriver.Chrome(service=Service(ChromeDriverManager().install()), options=options)
             ^^^^^^^^^^^^^^^^^^^^^^^^^^^^^^^^^^^^^^^^^^^^^^^^^^^^^^^^^^^^^^^^^^^^^^^^^^^^^^^^^^^
  File "/home/vboxuser/Desktop/FocoRadical/venv/lib/python3.12/site-packages/selenium/webdriver/chrome/webdriver.py", line 47, in __init__
    super().__init__(
  File "/home/vboxuser/Desktop/FocoRadical/venv/lib/python3.12/site-packages/selenium/webdriver/chromium/webdriver.py", line 69, in __init__
    super().__init__(command_executor=executor, options=options)
  File "/home/vboxuser/Desktop/FocoRadical/venv/lib/python3.12/site-packages/selenium/webdriver/remote/webdriver.py", line 261, in __init__
    self.start_session(capabilities)
  File "/home/vboxuser/Desktop/FocoRadical/venv/lib/python3.12/site-packages/selenium/webdriver/remote/webdriver.py", line 362, in start_session
    response = self.execute(Command.NEW_SESSION, caps)["value"]
               ^^^^^^^^^^^^^^^^^^^^^^^^^^^^^^^^^^^^^^^
  File "/home/vboxuser/Desktop/FocoRadical/venv/lib/python3.12/site-packages/selenium/webdriver/remote/webdriver.py", line 454, in execute
    self.error_handler.check_response(response)
  File "/home/vboxuser/Desktop/FocoRadical/venv/lib/python3.12/site-packages/selenium/webdriver/remote/errorhandler.py", line 232, in check_response
    raise exception_class(message, screen, stacktrace)
selenium.common.exceptions.SessionNotCreatedException: Message: session not created: probably user data directory is already in use, please specify a unique value for --user-data-dir argument, or don't use --user-data-dir; For documentation on this error, please visit: https://www.selenium.dev/documentation/webdriver/troubleshooting/errors#sessionnotcreatedexception
Stacktrace:
#0 0x5fc70655d87a <unknown>
#1 0x5fc7060022e0 <unknown>
#2 0x5fc70603c7bd <unknown>
#3 0x5fc706037ad7 <unknown>
#4 0x5fc706087e9e <unknown>
#5 0x5fc706087466 <unknown>
#6 0x5fc706079683 <unknown>
#7 0x5fc706045b5b <unknown>
#8 0x5fc706046f31 <unknown>
#9 0x5fc7065227cb <unknown>
#10 0x5fc7065265d4 <unknown>
#11 0x5fc7065092c9 <unknown>
#12 0x5fc706527178 <unknown>
#13 0x5fc7064ed6bf <unknown>
#14 0x5fc70654ae78 <unknown>
#15 0x5fc70654b056 <unknown>
#16 0x5fc70655cb96 <unknown>
#17 0x720a8009caa4 <unknown>
#18 0x720a80129c3c <unknown>

Traceback (most recent call last):
  File "/home/vboxuser/Desktop/FocoRadical/extract.py", line 19, in <module>
    driver = webdriver.Chrome(service=Service(ChromeDriverManager().install()), options=options)
             ^^^^^^^^^^^^^^^^^^^^^^^^^^^^^^^^^^^^^^^^^^^^^^^^^^^^^^^^^^^^^^^^^^^^^^^^^^^^^^^^^^^
  File "/home/vboxuser/Desktop/FocoRadical/venv/lib/python3.12/site-packages/selenium/webdriver/chrome/webdriver.py", line 47, in __init__
    super().__init__(
  File "/home/vboxuser/Desktop/FocoRadical/venv/lib/python3.12/site-packages/selenium/webdriver/chromium/webdriver.py", line 69, in __init__
    super().__init__(command_executor=executor, options=options)
  File "/home/vboxuser/Desktop/FocoRadical/venv/lib/python3.12/site-packages/selenium/webdriver/remote/webdriver.py", line 261, in __init__
    self.start_session(capabilities)
  File "/home/vboxuser/Desktop/FocoRadical/venv/lib/python3.12/site-packages/selenium/webdriver/remote/webdriver.py", line 362, in start_session
    response = self.execute(Command.NEW_SESSION, caps)["value"]
               ^^^^^^^^^^^^^^^^^^^^^^^^^^^^^^^^^^^^^^^
  File "/home/vboxuser/Desktop/FocoRadical/venv/lib/python3.12/site-packages/selenium/webdriver/remote/webdriver.py", line 454, in execute
    self.error_handler.check_response(response)
  File "/home/vboxuser/Desktop/FocoRadical/venv/lib/python3.12/site-packages/selenium/webdriver/remote/errorhandler.py", line 232, in check_response
    raise exception_class(message, screen, stacktrace)
selenium.common.exceptions.SessionNotCreatedException: Message: session not created: probably user data directory is already in use, please specify a unique value for --user-data-dir argument, or don't use --user-data-dir; For documentation on this error, please visit: https://www.selenium.dev/documentation/webdriver/troubleshooting/errors#sessionnotcreatedexception
Stacktrace:
#0 0x5edeb509687a <unknown>
#1 0x5edeb4b3b2e0 <unknown>
#2 0x5edeb4b757bd <unknown>
#3 0x5edeb4b70ad7 <unknown>
#4 0x5edeb4bc0e9e <unknown>
#5 0x5edeb4bc0466 <unknown>
#6 0x5edeb4bb2683 <unknown>
#7 0x5edeb4b7eb5b <unknown>
#8 0x5edeb4b7ff31 <unknown>
#9 0x5edeb505b7cb <unknown>
#10 0x5edeb505f5d4 <unknown>
#11 0x5edeb50422c9 <unknown>
#12 0x5edeb5060178 <unknown>
#13 0x5edeb50266bf <unknown>
#14 0x5edeb5083e78 <unknown>
#15 0x5edeb5084056 <unknown>
#16 0x5edeb5095b96 <unknown>
#17 0x7c52a3a9caa4 <unknown>
#18 0x7c52a3b29c3c <unknown>

Traceback (most recent call last):
  File "/home/vboxuser/Desktop/FocoRadical/extract.py", line 19, in <module>
    driver = webdriver.Chrome(service=Service(ChromeDriverManager().install()), options=options)
             ^^^^^^^^^^^^^^^^^^^^^^^^^^^^^^^^^^^^^^^^^^^^^^^^^^^^^^^^^^^^^^^^^^^^^^^^^^^^^^^^^^^
  File "/home/vboxuser/Desktop/FocoRadical/venv/lib/python3.12/site-packages/selenium/webdriver/chrome/webdriver.py", line 47, in __init__
    super().__init__(
  File "/home/vboxuser/Desktop/FocoRadical/venv/lib/python3.12/site-packages/selenium/webdriver/chromium/webdriver.py", line 69, in __init__
    super().__init__(command_executor=executor, options=options)
  File "/home/vboxuser/Desktop/FocoRadical/venv/lib/python3.12/site-packages/selenium/webdriver/remote/webdriver.py", line 261, in __init__
    self.start_session(capabilities)
  File "/home/vboxuser/Desktop/FocoRadical/venv/lib/python3.12/site-packages/selenium/webdriver/remote/webdriver.py", line 362, in start_session
    response = self.execute(Command.NEW_SESSION, caps)["value"]
               ^^^^^^^^^^^^^^^^^^^^^^^^^^^^^^^^^^^^^^^
  File "/home/vboxuser/Desktop/FocoRadical/venv/lib/python3.12/site-packages/selenium/webdriver/remote/webdriver.py", line 454, in execute
    self.error_handler.check_response(response)
  File "/home/vboxuser/Desktop/FocoRadical/venv/lib/python3.12/site-packages/selenium/webdriver/remote/errorhandler.py", line 232, in check_response
    raise exception_class(message, screen, stacktrace)
selenium.common.exceptions.SessionNotCreatedException: Message: session not created: probably user data directory is already in use, please specify a unique value for --user-data-dir argument, or don't use --user-data-dir; For documentation on this error, please visit: https://www.selenium.dev/documentation/webdriver/troubleshooting/errors#sessionnotcreatedexception
Stacktrace:
#0 0x5f4d1776987a <unknown>
#1 0x5f4d1720e2e0 <unknown>
#2 0x5f4d172487bd <unknown>
#3 0x5f4d17243ad7 <unknown>
#4 0x5f4d17293e9e <unknown>
#5 0x5f4d17293466 <unknown>
#6 0x5f4d17285683 <unknown>
#7 0x5f4d17251b5b <unknown>
#8 0x5f4d17252f31 <unknown>
#9 0x5f4d1772e7cb <unknown>
#10 0x5f4d177325d4 <unknown>
#11 0x5f4d177152c9 <unknown>
#12 0x5f4d17733178 <unknown>
#13 0x5f4d176f96bf <unknown>
#14 0x5f4d17756e78 <unknown>
#15 0x5f4d17757056 <unknown>
#16 0x5f4d17768b96 <unknown>
#17 0x70e05969caa4 <unknown>
#18 0x70e059729c3c <unknown>

Traceback (most recent call last):
  File "/home/vboxuser/Desktop/FocoRadical/extract.py", line 19, in <module>
    driver = webdriver.Chrome(service=Service(ChromeDriverManager().install()), options=options)
             ^^^^^^^^^^^^^^^^^^^^^^^^^^^^^^^^^^^^^^^^^^^^^^^^^^^^^^^^^^^^^^^^^^^^^^^^^^^^^^^^^^^
  File "/home/vboxuser/Desktop/FocoRadical/venv/lib/python3.12/site-packages/selenium/webdriver/chrome/webdriver.py", line 47, in __init__
    super().__init__(
  File "/home/vboxuser/Desktop/FocoRadical/venv/lib/python3.12/site-packages/selenium/webdriver/chromium/webdriver.py", line 69, in __init__
    super().__init__(command_executor=executor, options=options)
  File "/home/vboxuser/Desktop/FocoRadical/venv/lib/python3.12/site-packages/selenium/webdriver/remote/webdriver.py", line 261, in __init__
    self.start_session(capabilities)
  File "/home/vboxuser/Desktop/FocoRadical/venv/lib/python3.12/site-packages/selenium/webdriver/remote/webdriver.py", line 362, in start_session
    response = self.execute(Command.NEW_SESSION, caps)["value"]
               ^^^^^^^^^^^^^^^^^^^^^^^^^^^^^^^^^^^^^^^
  File "/home/vboxuser/Desktop/FocoRadical/venv/lib/python3.12/site-packages/selenium/webdriver/remote/webdriver.py", line 454, in execute
    self.error_handler.check_response(response)
  File "/home/vboxuser/Desktop/FocoRadical/venv/lib/python3.12/site-packages/selenium/webdriver/remote/errorhandler.py", line 232, in check_response
    raise exception_class(message, screen, stacktrace)
selenium.common.exceptions.SessionNotCreatedException: Message: session not created: probably user data directory is already in use, please specify a unique value for --user-data-dir argument, or don't use --user-data-dir; For documentation on this error, please visit: https://www.selenium.dev/documentation/webdriver/troubleshooting/errors#sessionnotcreatedexception
Stacktrace:
#0 0x566e051a287a <unknown>
#1 0x566e04c472e0 <unknown>
#2 0x566e04c817bd <unknown>
#3 0x566e04c7cad7 <unknown>
#4 0x566e04ccce9e <unknown>
#5 0x566e04ccc466 <unknown>
#6 0x566e04cbe683 <unknown>
#7 0x566e04c8ab5b <unknown>
#8 0x566e04c8bf31 <unknown>
#9 0x566e051677cb <unknown>
#10 0x566e0516b5d4 <unknown>
#11 0x566e0514e2c9 <unknown>
#12 0x566e0516c178 <unknown>
#13 0x566e051326bf <unknown>
#14 0x566e0518fe78 <unknown>
#15 0x566e05190056 <unknown>
#16 0x566e051a1b96 <unknown>
#17 0x74fc85c9caa4 <unknown>
#18 0x74fc85d29c3c <unknown>

Traceback (most recent call last):
  File "/home/vboxuser/Desktop/FocoRadical/extract.py", line 19, in <module>
    driver = webdriver.Chrome(service=Service(ChromeDriverManager().install()), options=options)
             ^^^^^^^^^^^^^^^^^^^^^^^^^^^^^^^^^^^^^^^^^^^^^^^^^^^^^^^^^^^^^^^^^^^^^^^^^^^^^^^^^^^
  File "/home/vboxuser/Desktop/FocoRadical/venv/lib/python3.12/site-packages/selenium/webdriver/chrome/webdriver.py", line 47, in __init__
    super().__init__(
  File "/home/vboxuser/Desktop/FocoRadical/venv/lib/python3.12/site-packages/selenium/webdriver/chromium/webdriver.py", line 69, in __init__
    super().__init__(command_executor=executor, options=options)
  File "/home/vboxuser/Desktop/FocoRadical/venv/lib/python3.12/site-packages/selenium/webdriver/remote/webdriver.py", line 261, in __init__
    self.start_session(capabilities)
  File "/home/vboxuser/Desktop/FocoRadical/venv/lib/python3.12/site-packages/selenium/webdriver/remote/webdriver.py", line 362, in start_session
    response = self.execute(Command.NEW_SESSION, caps)["value"]
               ^^^^^^^^^^^^^^^^^^^^^^^^^^^^^^^^^^^^^^^
  File "/home/vboxuser/Desktop/FocoRadical/venv/lib/python3.12/site-packages/selenium/webdriver/remote/webdriver.py", line 454, in execute
    self.error_handler.check_response(response)
  File "/home/vboxuser/Desktop/FocoRadical/venv/lib/python3.12/site-packages/selenium/webdriver/remote/errorhandler.py", line 232, in check_response
    raise exception_class(message, screen, stacktrace)
selenium.common.exceptions.SessionNotCreatedException: Message: session not created: probably user data directory is already in use, please specify a unique value for --user-data-dir argument, or don't use --user-data-dir; For documentation on this error, please visit: https://www.selenium.dev/documentation/webdriver/troubleshooting/errors#sessionnotcreatedexception
Stacktrace:
#0 0x638f72ff587a <unknown>
#1 0x638f72a9a2e0 <unknown>
#2 0x638f72ad47bd <unknown>
#3 0x638f72acfad7 <unknown>
#4 0x638f72b1fe9e <unknown>
#5 0x638f72b1f466 <unknown>
#6 0x638f72b11683 <unknown>
#7 0x638f72addb5b <unknown>
#8 0x638f72adef31 <unknown>
#9 0x638f72fba7cb <unknown>
#10 0x638f72fbe5d4 <unknown>
#11 0x638f72fa12c9 <unknown>
#12 0x638f72fbf178 <unknown>
#13 0x638f72f856bf <unknown>
#14 0x638f72fe2e78 <unknown>
#15 0x638f72fe3056 <unknown>
#16 0x638f72ff4b96 <unknown>
#17 0x71725d89caa4 <unknown>
#18 0x71725d929c3c <unknown>

Traceback (most recent call last):
  File "/home/vboxuser/Desktop/FocoRadical/extract.py", line 19, in <module>
    driver = webdriver.Chrome(service=Service(ChromeDriverManager().install()), options=options)
             ^^^^^^^^^^^^^^^^^^^^^^^^^^^^^^^^^^^^^^^^^^^^^^^^^^^^^^^^^^^^^^^^^^^^^^^^^^^^^^^^^^^
  File "/home/vboxuser/Desktop/FocoRadical/venv/lib/python3.12/site-packages/selenium/webdriver/chrome/webdriver.py", line 47, in __init__
    super().__init__(
  File "/home/vboxuser/Desktop/FocoRadical/venv/lib/python3.12/site-packages/selenium/webdriver/chromium/webdriver.py", line 69, in __init__
    super().__init__(command_executor=executor, options=options)
  File "/home/vboxuser/Desktop/FocoRadical/venv/lib/python3.12/site-packages/selenium/webdriver/remote/webdriver.py", line 261, in __init__
    self.start_session(capabilities)
  File "/home/vboxuser/Desktop/FocoRadical/venv/lib/python3.12/site-packages/selenium/webdriver/remote/webdriver.py", line 362, in start_session
    response = self.execute(Command.NEW_SESSION, caps)["value"]
               ^^^^^^^^^^^^^^^^^^^^^^^^^^^^^^^^^^^^^^^
  File "/home/vboxuser/Desktop/FocoRadical/venv/lib/python3.12/site-packages/selenium/webdriver/remote/webdriver.py", line 454, in execute
    self.error_handler.check_response(response)
  File "/home/vboxuser/Desktop/FocoRadical/venv/lib/python3.12/site-packages/selenium/webdriver/remote/errorhandler.py", line 232, in check_response
    raise exception_class(message, screen, stacktrace)
selenium.common.exceptions.SessionNotCreatedException: Message: session not created: probably user data directory is already in use, please specify a unique value for --user-data-dir argument, or don't use --user-data-dir; For documentation on this error, please visit: https://www.selenium.dev/documentation/webdriver/troubleshooting/errors#sessionnotcreatedexception
Stacktrace:
#0 0x5dcaf752287a <unknown>
#1 0x5dcaf6fc72e0 <unknown>
#2 0x5dcaf70017bd <unknown>
#3 0x5dcaf6ffcad7 <unknown>
#4 0x5dcaf704ce9e <unknown>
#5 0x5dcaf704c466 <unknown>
#6 0x5dcaf703e683 <unknown>
#7 0x5dcaf700ab5b <unknown>
#8 0x5dcaf700bf31 <unknown>
#9 0x5dcaf74e77cb <unknown>
#10 0x5dcaf74eb5d4 <unknown>
#11 0x5dcaf74ce2c9 <unknown>
#12 0x5dcaf74ec178 <unknown>
#13 0x5dcaf74b26bf <unknown>
#14 0x5dcaf750fe78 <unknown>
#15 0x5dcaf7510056 <unknown>
#16 0x5dcaf7521b96 <unknown>
#17 0x790b1169caa4 <unknown>
#18 0x790b11729c3c <unknown>

Traceback (most recent call last):
  File "/home/vboxuser/Desktop/FocoRadical/extract.py", line 19, in <module>
    driver = webdriver.Chrome(service=Service(ChromeDriverManager().install()), options=options)
             ^^^^^^^^^^^^^^^^^^^^^^^^^^^^^^^^^^^^^^^^^^^^^^^^^^^^^^^^^^^^^^^^^^^^^^^^^^^^^^^^^^^
  File "/home/vboxuser/Desktop/FocoRadical/venv/lib/python3.12/site-packages/selenium/webdriver/chrome/webdriver.py", line 47, in __init__
    super().__init__(
  File "/home/vboxuser/Desktop/FocoRadical/venv/lib/python3.12/site-packages/selenium/webdriver/chromium/webdriver.py", line 69, in __init__
    super().__init__(command_executor=executor, options=options)
  File "/home/vboxuser/Desktop/FocoRadical/venv/lib/python3.12/site-packages/selenium/webdriver/remote/webdriver.py", line 261, in __init__
    self.start_session(capabilities)
  File "/home/vboxuser/Desktop/FocoRadical/venv/lib/python3.12/site-packages/selenium/webdriver/remote/webdriver.py", line 362, in start_session
    response = self.execute(Command.NEW_SESSION, caps)["value"]
               ^^^^^^^^^^^^^^^^^^^^^^^^^^^^^^^^^^^^^^^
  File "/home/vboxuser/Desktop/FocoRadical/venv/lib/python3.12/site-packages/selenium/webdriver/remote/webdriver.py", line 454, in execute
    self.error_handler.check_response(response)
  File "/home/vboxuser/Desktop/FocoRadical/venv/lib/python3.12/site-packages/selenium/webdriver/remote/errorhandler.py", line 232, in check_response
    raise exception_class(message, screen, stacktrace)
selenium.common.exceptions.SessionNotCreatedException: Message: session not created: probably user data directory is already in use, please specify a unique value for --user-data-dir argument, or don't use --user-data-dir; For documentation on this error, please visit: https://www.selenium.dev/documentation/webdriver/troubleshooting/errors#sessionnotcreatedexception
Stacktrace:
#0 0x5b0003ce487a <unknown>
#1 0x5b00037892e0 <unknown>
#2 0x5b00037c37bd <unknown>
#3 0x5b00037bead7 <unknown>
#4 0x5b000380ee9e <unknown>
#5 0x5b000380e466 <unknown>
#6 0x5b0003800683 <unknown>
#7 0x5b00037ccb5b <unknown>
#8 0x5b00037cdf31 <unknown>
#9 0x5b0003ca97cb <unknown>
#10 0x5b0003cad5d4 <unknown>
#11 0x5b0003c902c9 <unknown>
#12 0x5b0003cae178 <unknown>
#13 0x5b0003c746bf <unknown>
#14 0x5b0003cd1e78 <unknown>
#15 0x5b0003cd2056 <unknown>
#16 0x5b0003ce3b96 <unknown>
#17 0x794860e9caa4 <unknown>
#18 0x794860f29c3c <unknown>

Traceback (most recent call last):
  File "/home/vboxuser/Desktop/FocoRadical/extract.py", line 19, in <module>
    driver = webdriver.Chrome(service=Service(ChromeDriverManager().install()), options=options)
             ^^^^^^^^^^^^^^^^^^^^^^^^^^^^^^^^^^^^^^^^^^^^^^^^^^^^^^^^^^^^^^^^^^^^^^^^^^^^^^^^^^^
  File "/home/vboxuser/Desktop/FocoRadical/venv/lib/python3.12/site-packages/selenium/webdriver/chrome/webdriver.py", line 47, in __init__
    super().__init__(
  File "/home/vboxuser/Desktop/FocoRadical/venv/lib/python3.12/site-packages/selenium/webdriver/chromium/webdriver.py", line 69, in __init__
    super().__init__(command_executor=executor, options=options)
  File "/home/vboxuser/Desktop/FocoRadical/venv/lib/python3.12/site-packages/selenium/webdriver/remote/webdriver.py", line 261, in __init__
    self.start_session(capabilities)
  File "/home/vboxuser/Desktop/FocoRadical/venv/lib/python3.12/site-packages/selenium/webdriver/remote/webdriver.py", line 362, in start_session
    response = self.execute(Command.NEW_SESSION, caps)["value"]
               ^^^^^^^^^^^^^^^^^^^^^^^^^^^^^^^^^^^^^^^
  File "/home/vboxuser/Desktop/FocoRadical/venv/lib/python3.12/site-packages/selenium/webdriver/remote/webdriver.py", line 454, in execute
    self.error_handler.check_response(response)
  File "/home/vboxuser/Desktop/FocoRadical/venv/lib/python3.12/site-packages/selenium/webdriver/remote/errorhandler.py", line 232, in check_response
    raise exception_class(message, screen, stacktrace)
selenium.common.exceptions.SessionNotCreatedException: Message: session not created: probably user data directory is already in use, please specify a unique value for --user-data-dir argument, or don't use --user-data-dir; For documentation on this error, please visit: https://www.selenium.dev/documentation/webdriver/troubleshooting/errors#sessionnotcreatedexception
Stacktrace:
#0 0x59a12190e87a <unknown>
#1 0x59a1213b32e0 <unknown>
#2 0x59a1213ed7bd <unknown>
#3 0x59a1213e8ad7 <unknown>
#4 0x59a121438e9e <unknown>
#5 0x59a121438466 <unknown>
#6 0x59a12142a683 <unknown>
#7 0x59a1213f6b5b <unknown>
#8 0x59a1213f7f31 <unknown>
#9 0x59a1218d37cb <unknown>
#10 0x59a1218d75d4 <unknown>
#11 0x59a1218ba2c9 <unknown>
#12 0x59a1218d8178 <unknown>
#13 0x59a12189e6bf <unknown>
#14 0x59a1218fbe78 <unknown>
#15 0x59a1218fc056 <unknown>
#16 0x59a12190db96 <unknown>
#17 0x729a9089caa4 <unknown>
#18 0x729a90929c3c <unknown>

Traceback (most recent call last):
  File "/home/vboxuser/Desktop/FocoRadical/extract.py", line 19, in <module>
    driver = webdriver.Chrome(service=Service(ChromeDriverManager().install()), options=options)
             ^^^^^^^^^^^^^^^^^^^^^^^^^^^^^^^^^^^^^^^^^^^^^^^^^^^^^^^^^^^^^^^^^^^^^^^^^^^^^^^^^^^
  File "/home/vboxuser/Desktop/FocoRadical/venv/lib/python3.12/site-packages/selenium/webdriver/chrome/webdriver.py", line 47, in __init__
    super().__init__(
  File "/home/vboxuser/Desktop/FocoRadical/venv/lib/python3.12/site-packages/selenium/webdriver/chromium/webdriver.py", line 69, in __init__
    super().__init__(command_executor=executor, options=options)
  File "/home/vboxuser/Desktop/FocoRadical/venv/lib/python3.12/site-packages/selenium/webdriver/remote/webdriver.py", line 261, in __init__
    self.start_session(capabilities)
  File "/home/vboxuser/Desktop/FocoRadical/venv/lib/python3.12/site-packages/selenium/webdriver/remote/webdriver.py", line 362, in start_session
    response = self.execute(Command.NEW_SESSION, caps)["value"]
               ^^^^^^^^^^^^^^^^^^^^^^^^^^^^^^^^^^^^^^^
  File "/home/vboxuser/Desktop/FocoRadical/venv/lib/python3.12/site-packages/selenium/webdriver/remote/webdriver.py", line 454, in execute
    self.error_handler.check_response(response)
  File "/home/vboxuser/Desktop/FocoRadical/venv/lib/python3.12/site-packages/selenium/webdriver/remote/errorhandler.py", line 232, in check_response
    raise exception_class(message, screen, stacktrace)
selenium.common.exceptions.SessionNotCreatedException: Message: session not created: probably user data directory is already in use, please specify a unique value for --user-data-dir argument, or don't use --user-data-dir; For documentation on this error, please visit: https://www.selenium.dev/documentation/webdriver/troubleshooting/errors#sessionnotcreatedexception
Stacktrace:
#0 0x55986839687a <unknown>
#1 0x559867e3b2e0 <unknown>
#2 0x559867e757bd <unknown>
#3 0x559867e70ad7 <unknown>
#4 0x559867ec0e9e <unknown>
#5 0x559867ec0466 <unknown>
#6 0x559867eb2683 <unknown>
#7 0x559867e7eb5b <unknown>
#8 0x559867e7ff31 <unknown>
#9 0x55986835b7cb <unknown>
#10 0x55986835f5d4 <unknown>
#11 0x5598683422c9 <unknown>
#12 0x559868360178 <unknown>
#13 0x5598683266bf <unknown>
#14 0x559868383e78 <unknown>
#15 0x559868384056 <unknown>
#16 0x559868395b96 <unknown>
#17 0x7c0bc9a9caa4 <unknown>
#18 0x7c0bc9b29c3c <unknown>

Traceback (most recent call last):
  File "/home/vboxuser/Desktop/FocoRadical/extract.py", line 19, in <module>
    driver = webdriver.Chrome(service=Service(ChromeDriverManager().install()), options=options)
             ^^^^^^^^^^^^^^^^^^^^^^^^^^^^^^^^^^^^^^^^^^^^^^^^^^^^^^^^^^^^^^^^^^^^^^^^^^^^^^^^^^^
  File "/home/vboxuser/Desktop/FocoRadical/venv/lib/python3.12/site-packages/selenium/webdriver/chrome/webdriver.py", line 47, in __init__
    super().__init__(
  File "/home/vboxuser/Desktop/FocoRadical/venv/lib/python3.12/site-packages/selenium/webdriver/chromium/webdriver.py", line 69, in __init__
    super().__init__(command_executor=executor, options=options)
  File "/home/vboxuser/Desktop/FocoRadical/venv/lib/python3.12/site-packages/selenium/webdriver/remote/webdriver.py", line 261, in __init__
    self.start_session(capabilities)
  File "/home/vboxuser/Desktop/FocoRadical/venv/lib/python3.12/site-packages/selenium/webdriver/remote/webdriver.py", line 362, in start_session
    response = self.execute(Command.NEW_SESSION, caps)["value"]
               ^^^^^^^^^^^^^^^^^^^^^^^^^^^^^^^^^^^^^^^
  File "/home/vboxuser/Desktop/FocoRadical/venv/lib/python3.12/site-packages/selenium/webdriver/remote/webdriver.py", line 454, in execute
    self.error_handler.check_response(response)
  File "/home/vboxuser/Desktop/FocoRadical/venv/lib/python3.12/site-packages/selenium/webdriver/remote/errorhandler.py", line 232, in check_response
    raise exception_class(message, screen, stacktrace)
selenium.common.exceptions.SessionNotCreatedException: Message: session not created: probably user data directory is already in use, please specify a unique value for --user-data-dir argument, or don't use --user-data-dir; For documentation on this error, please visit: https://www.selenium.dev/documentation/webdriver/troubleshooting/errors#sessionnotcreatedexception
Stacktrace:
#0 0x5c079b52387a <unknown>
#1 0x5c079afc82e0 <unknown>
#2 0x5c079b0027bd <unknown>
#3 0x5c079affdad7 <unknown>
#4 0x5c079b04de9e <unknown>
#5 0x5c079b04d466 <unknown>
#6 0x5c079b03f683 <unknown>
#7 0x5c079b00bb5b <unknown>
#8 0x5c079b00cf31 <unknown>
#9 0x5c079b4e87cb <unknown>
#10 0x5c079b4ec5d4 <unknown>
#11 0x5c079b4cf2c9 <unknown>
#12 0x5c079b4ed178 <unknown>
#13 0x5c079b4b36bf <unknown>
#14 0x5c079b510e78 <unknown>
#15 0x5c079b511056 <unknown>
#16 0x5c079b522b96 <unknown>
#17 0x70ab5549caa4 <unknown>
#18 0x70ab55529c3c <unknown>

Traceback (most recent call last):
  File "/home/vboxuser/Desktop/FocoRadical/extract.py", line 19, in <module>
    driver = webdriver.Chrome(service=Service(ChromeDriverManager().install()), options=options)
             ^^^^^^^^^^^^^^^^^^^^^^^^^^^^^^^^^^^^^^^^^^^^^^^^^^^^^^^^^^^^^^^^^^^^^^^^^^^^^^^^^^^
  File "/home/vboxuser/Desktop/FocoRadical/venv/lib/python3.12/site-packages/selenium/webdriver/chrome/webdriver.py", line 47, in __init__
    super().__init__(
  File "/home/vboxuser/Desktop/FocoRadical/venv/lib/python3.12/site-packages/selenium/webdriver/chromium/webdriver.py", line 69, in __init__
    super().__init__(command_executor=executor, options=options)
  File "/home/vboxuser/Desktop/FocoRadical/venv/lib/python3.12/site-packages/selenium/webdriver/remote/webdriver.py", line 261, in __init__
    self.start_session(capabilities)
  File "/home/vboxuser/Desktop/FocoRadical/venv/lib/python3.12/site-packages/selenium/webdriver/remote/webdriver.py", line 362, in start_session
    response = self.execute(Command.NEW_SESSION, caps)["value"]
               ^^^^^^^^^^^^^^^^^^^^^^^^^^^^^^^^^^^^^^^
  File "/home/vboxuser/Desktop/FocoRadical/venv/lib/python3.12/site-packages/selenium/webdriver/remote/webdriver.py", line 454, in execute
    self.error_handler.check_response(response)
  File "/home/vboxuser/Desktop/FocoRadical/venv/lib/python3.12/site-packages/selenium/webdriver/remote/errorhandler.py", line 232, in check_response
    raise exception_class(message, screen, stacktrace)
selenium.common.exceptions.SessionNotCreatedException: Message: session not created: probably user data directory is already in use, please specify a unique value for --user-data-dir argument, or don't use --user-data-dir; For documentation on this error, please visit: https://www.selenium.dev/documentation/webdriver/troubleshooting/errors#sessionnotcreatedexception
Stacktrace:
#0 0x59cc3bb1287a <unknown>
#1 0x59cc3b5b72e0 <unknown>
#2 0x59cc3b5f17bd <unknown>
#3 0x59cc3b5ecad7 <unknown>
#4 0x59cc3b63ce9e <unknown>
#5 0x59cc3b63c466 <unknown>
#6 0x59cc3b62e683 <unknown>
#7 0x59cc3b5fab5b <unknown>
#8 0x59cc3b5fbf31 <unknown>
#9 0x59cc3bad77cb <unknown>
#10 0x59cc3badb5d4 <unknown>
#11 0x59cc3babe2c9 <unknown>
#12 0x59cc3badc178 <unknown>
#13 0x59cc3baa26bf <unknown>
#14 0x59cc3baffe78 <unknown>
#15 0x59cc3bb00056 <unknown>
#16 0x59cc3bb11b96 <unknown>
#17 0x7773e9a9caa4 <unknown>
#18 0x7773e9b29c3c <unknown>

Traceback (most recent call last):
  File "/home/vboxuser/Desktop/FocoRadical/extract.py", line 19, in <module>
    driver = webdriver.Chrome(service=Service(ChromeDriverManager().install()), options=options)
             ^^^^^^^^^^^^^^^^^^^^^^^^^^^^^^^^^^^^^^^^^^^^^^^^^^^^^^^^^^^^^^^^^^^^^^^^^^^^^^^^^^^
  File "/home/vboxuser/Desktop/FocoRadical/venv/lib/python3.12/site-packages/selenium/webdriver/chrome/webdriver.py", line 47, in __init__
    super().__init__(
  File "/home/vboxuser/Desktop/FocoRadical/venv/lib/python3.12/site-packages/selenium/webdriver/chromium/webdriver.py", line 69, in __init__
    super().__init__(command_executor=executor, options=options)
  File "/home/vboxuser/Desktop/FocoRadical/venv/lib/python3.12/site-packages/selenium/webdriver/remote/webdriver.py", line 261, in __init__
    self.start_session(capabilities)
  File "/home/vboxuser/Desktop/FocoRadical/venv/lib/python3.12/site-packages/selenium/webdriver/remote/webdriver.py", line 362, in start_session
    response = self.execute(Command.NEW_SESSION, caps)["value"]
               ^^^^^^^^^^^^^^^^^^^^^^^^^^^^^^^^^^^^^^^
  File "/home/vboxuser/Desktop/FocoRadical/venv/lib/python3.12/site-packages/selenium/webdriver/remote/webdriver.py", line 454, in execute
    self.error_handler.check_response(response)
  File "/home/vboxuser/Desktop/FocoRadical/venv/lib/python3.12/site-packages/selenium/webdriver/remote/errorhandler.py", line 232, in check_response
    raise exception_class(message, screen, stacktrace)
selenium.common.exceptions.SessionNotCreatedException: Message: session not created: probably user data directory is already in use, please specify a unique value for --user-data-dir argument, or don't use --user-data-dir; For documentation on this error, please visit: https://www.selenium.dev/documentation/webdriver/troubleshooting/errors#sessionnotcreatedexception
Stacktrace:
#0 0x65085a15e87a <unknown>
#1 0x650859c032e0 <unknown>
#2 0x650859c3d7bd <unknown>
#3 0x650859c38ad7 <unknown>
#4 0x650859c88e9e <unknown>
#5 0x650859c88466 <unknown>
#6 0x650859c7a683 <unknown>
#7 0x650859c46b5b <unknown>
#8 0x650859c47f31 <unknown>
#9 0x65085a1237cb <unknown>
#10 0x65085a1275d4 <unknown>
#11 0x65085a10a2c9 <unknown>
#12 0x65085a128178 <unknown>
#13 0x65085a0ee6bf <unknown>
#14 0x65085a14be78 <unknown>
#15 0x65085a14c056 <unknown>
#16 0x65085a15db96 <unknown>
#17 0x756f7009caa4 <unknown>
#18 0x756f70129c3c <unknown>

Traceback (most recent call last):
  File "/home/vboxuser/Desktop/FocoRadical/extract.py", line 19, in <module>
    driver = webdriver.Chrome(service=Service(ChromeDriverManager().install()), options=options)
             ^^^^^^^^^^^^^^^^^^^^^^^^^^^^^^^^^^^^^^^^^^^^^^^^^^^^^^^^^^^^^^^^^^^^^^^^^^^^^^^^^^^
  File "/home/vboxuser/Desktop/FocoRadical/venv/lib/python3.12/site-packages/selenium/webdriver/chrome/webdriver.py", line 47, in __init__
    super().__init__(
  File "/home/vboxuser/Desktop/FocoRadical/venv/lib/python3.12/site-packages/selenium/webdriver/chromium/webdriver.py", line 69, in __init__
    super().__init__(command_executor=executor, options=options)
  File "/home/vboxuser/Desktop/FocoRadical/venv/lib/python3.12/site-packages/selenium/webdriver/remote/webdriver.py", line 261, in __init__
    self.start_session(capabilities)
  File "/home/vboxuser/Desktop/FocoRadical/venv/lib/python3.12/site-packages/selenium/webdriver/remote/webdriver.py", line 362, in start_session
    response = self.execute(Command.NEW_SESSION, caps)["value"]
               ^^^^^^^^^^^^^^^^^^^^^^^^^^^^^^^^^^^^^^^
  File "/home/vboxuser/Desktop/FocoRadical/venv/lib/python3.12/site-packages/selenium/webdriver/remote/webdriver.py", line 454, in execute
    self.error_handler.check_response(response)
  File "/home/vboxuser/Desktop/FocoRadical/venv/lib/python3.12/site-packages/selenium/webdriver/remote/errorhandler.py", line 232, in check_response
    raise exception_class(message, screen, stacktrace)
selenium.common.exceptions.SessionNotCreatedException: Message: session not created: probably user data directory is already in use, please specify a unique value for --user-data-dir argument, or don't use --user-data-dir; For documentation on this error, please visit: https://www.selenium.dev/documentation/webdriver/troubleshooting/errors#sessionnotcreatedexception
Stacktrace:
#0 0x6126a8f2387a <unknown>
#1 0x6126a89c82e0 <unknown>
#2 0x6126a8a027bd <unknown>
#3 0x6126a89fdad7 <unknown>
#4 0x6126a8a4de9e <unknown>
#5 0x6126a8a4d466 <unknown>
#6 0x6126a8a3f683 <unknown>
#7 0x6126a8a0bb5b <unknown>
#8 0x6126a8a0cf31 <unknown>
#9 0x6126a8ee87cb <unknown>
#10 0x6126a8eec5d4 <unknown>
#11 0x6126a8ecf2c9 <unknown>
#12 0x6126a8eed178 <unknown>
#13 0x6126a8eb36bf <unknown>
#14 0x6126a8f10e78 <unknown>
#15 0x6126a8f11056 <unknown>
#16 0x6126a8f22b96 <unknown>
#17 0x7eb757a9caa4 <unknown>
#18 0x7eb757b29c3c <unknown>

